[2025-09-09T15:26:55.790+0000] {local_task_job_runner.py:123} INFO - ::group::Pre task execution logs
[2025-09-09T15:26:55.898+0000] {taskinstance.py:2612} INFO - Dependencies all met for dep_context=non-requeueable deps ti=<TaskInstance: currency_etl.load manual__2025-09-09T15:26:44.120550+00:00 [queued]>
[2025-09-09T15:26:55.918+0000] {taskinstance.py:2612} INFO - Dependencies all met for dep_context=requeueable deps ti=<TaskInstance: currency_etl.load manual__2025-09-09T15:26:44.120550+00:00 [queued]>
[2025-09-09T15:26:55.919+0000] {taskinstance.py:2865} INFO - Starting attempt 1 of 2
[2025-09-09T15:26:55.955+0000] {taskinstance.py:2888} INFO - Executing <Task(BashOperator): load> on 2025-09-09 15:26:44.120550+00:00
[2025-09-09T15:26:55.978+0000] {standard_task_runner.py:104} INFO - Running: ['***', 'tasks', 'run', 'currency_etl', 'load', 'manual__2025-09-09T15:26:44.120550+00:00', '--job-id', '15', '--raw', '--subdir', 'DAGS_FOLDER/currency_etl.py', '--cfg-path', '/tmp/tmptd4z5mtw']
[2025-09-09T15:26:55.985+0000] {standard_task_runner.py:105} INFO - Job 15: Subtask load
[2025-09-09T15:26:55.986+0000] {logging_mixin.py:190} WARNING - /home/***/.local/lib/python3.12/site-packages/***/task/task_runner/standard_task_runner.py:70 DeprecationWarning: This process (pid=403) is multi-threaded, use of fork() may lead to deadlocks in the child.
[2025-09-09T15:26:55.988+0000] {standard_task_runner.py:72} INFO - Started process 404 to run task
[2025-09-09T15:26:56.283+0000] {task_command.py:467} INFO - Running <TaskInstance: currency_etl.load manual__2025-09-09T15:26:44.120550+00:00 [running]> on host faea9c4e3492
[2025-09-09T15:26:56.693+0000] {taskinstance.py:3131} INFO - Exporting env vars: AIRFLOW_CTX_DAG_OWNER='***' AIRFLOW_CTX_DAG_ID='currency_etl' AIRFLOW_CTX_TASK_ID='load' AIRFLOW_CTX_EXECUTION_DATE='2025-09-09T15:26:44.120550+00:00' AIRFLOW_CTX_TRY_NUMBER='1' AIRFLOW_CTX_DAG_RUN_ID='manual__2025-09-09T15:26:44.120550+00:00'
[2025-09-09T15:26:56.695+0000] {taskinstance.py:731} INFO - ::endgroup::
[2025-09-09T15:26:56.726+0000] {subprocess.py:63} INFO - Tmp dir root location: /tmp
[2025-09-09T15:26:56.729+0000] {subprocess.py:75} INFO - Running command: ['/usr/bin/bash', '-c', 'python /opt/***/scripts/load.py']
[2025-09-09T15:26:56.755+0000] {subprocess.py:86} INFO - Output:
[2025-09-09T15:26:59.459+0000] {subprocess.py:93} INFO - Traceback (most recent call last):
[2025-09-09T15:26:59.461+0000] {subprocess.py:93} INFO -   File "/opt/***/scripts/load.py", line 53, in <module>
[2025-09-09T15:26:59.466+0000] {subprocess.py:93} INFO -     sql = Path("sql/create_tables.sql").read_text()
[2025-09-09T15:26:59.467+0000] {subprocess.py:93} INFO -           ^^^^^^^^^^^^^^^^^^^^^^^^^^^^^^^^^^^^^^^^^
[2025-09-09T15:26:59.469+0000] {subprocess.py:93} INFO -   File "/usr/local/lib/python3.12/pathlib.py", line 1027, in read_text
[2025-09-09T15:26:59.470+0000] {subprocess.py:93} INFO -     with self.open(mode='r', encoding=encoding, errors=errors) as f:
[2025-09-09T15:26:59.471+0000] {subprocess.py:93} INFO -          ^^^^^^^^^^^^^^^^^^^^^^^^^^^^^^^^^^^^^^^^^^^^^^^^^^^^^
[2025-09-09T15:26:59.472+0000] {subprocess.py:93} INFO -   File "/usr/local/lib/python3.12/pathlib.py", line 1013, in open
[2025-09-09T15:26:59.473+0000] {subprocess.py:93} INFO -     return io.open(self, mode, buffering, encoding, errors, newline)
[2025-09-09T15:26:59.474+0000] {subprocess.py:93} INFO -            ^^^^^^^^^^^^^^^^^^^^^^^^^^^^^^^^^^^^^^^^^^^^^^^^^^^^^^^^^
[2025-09-09T15:26:59.475+0000] {subprocess.py:93} INFO - FileNotFoundError: [Errno 2] No such file or directory: 'sql/create_tables.sql'
[2025-09-09T15:26:59.666+0000] {subprocess.py:97} INFO - Command exited with return code 1
[2025-09-09T15:26:59.754+0000] {taskinstance.py:3310} ERROR - Task failed with exception
Traceback (most recent call last):
  File "/home/airflow/.local/lib/python3.12/site-packages/airflow/models/taskinstance.py", line 767, in _execute_task
    result = _execute_callable(context=context, **execute_callable_kwargs)
             ^^^^^^^^^^^^^^^^^^^^^^^^^^^^^^^^^^^^^^^^^^^^^^^^^^^^^^^^^^^^^
  File "/home/airflow/.local/lib/python3.12/site-packages/airflow/models/taskinstance.py", line 733, in _execute_callable
    return ExecutionCallableRunner(
           ^^^^^^^^^^^^^^^^^^^^^^^^
  File "/home/airflow/.local/lib/python3.12/site-packages/airflow/utils/operator_helpers.py", line 252, in run
    return self.func(*args, **kwargs)
           ^^^^^^^^^^^^^^^^^^^^^^^^^^
  File "/home/airflow/.local/lib/python3.12/site-packages/airflow/models/baseoperator.py", line 406, in wrapper
    return func(self, *args, **kwargs)
           ^^^^^^^^^^^^^^^^^^^^^^^^^^^
  File "/home/airflow/.local/lib/python3.12/site-packages/airflow/operators/bash.py", line 249, in execute
    raise AirflowException(
airflow.exceptions.AirflowException: Bash command failed. The command returned a non-zero exit code 1.
[2025-09-09T15:26:59.776+0000] {taskinstance.py:1225} INFO - Marking task as UP_FOR_RETRY. dag_id=currency_etl, task_id=load, run_id=manual__2025-09-09T15:26:44.120550+00:00, execution_date=20250909T152644, start_date=20250909T152655, end_date=20250909T152659
[2025-09-09T15:26:59.828+0000] {taskinstance.py:340} INFO - ::group::Post task execution logs
[2025-09-09T15:26:59.829+0000] {standard_task_runner.py:124} ERROR - Failed to execute job 15 for task load (Bash command failed. The command returned a non-zero exit code 1.; 404)
Traceback (most recent call last):
  File "/home/airflow/.local/lib/python3.12/site-packages/airflow/task/task_runner/standard_task_runner.py", line 117, in _start_by_fork
    ret = args.func(args, dag=self.dag)
          ^^^^^^^^^^^^^^^^^^^^^^^^^^^^^
  File "/home/airflow/.local/lib/python3.12/site-packages/airflow/cli/cli_config.py", line 49, in command
    return func(*args, **kwargs)
           ^^^^^^^^^^^^^^^^^^^^^
  File "/home/airflow/.local/lib/python3.12/site-packages/airflow/utils/cli.py", line 115, in wrapper
    return f(*args, **kwargs)
           ^^^^^^^^^^^^^^^^^^
  File "/home/airflow/.local/lib/python3.12/site-packages/airflow/cli/commands/task_command.py", line 483, in task_run
    task_return_code = _run_task_by_selected_method(args, _dag, ti)
                       ^^^^^^^^^^^^^^^^^^^^^^^^^^^^^^^^^^^^^^^^^^^^
  File "/home/airflow/.local/lib/python3.12/site-packages/airflow/cli/commands/task_command.py", line 256, in _run_task_by_selected_method
    return _run_raw_task(args, ti)
           ^^^^^^^^^^^^^^^^^^^^^^^
  File "/home/airflow/.local/lib/python3.12/site-packages/airflow/cli/commands/task_command.py", line 341, in _run_raw_task
    return ti._run_raw_task(
           ^^^^^^^^^^^^^^^^^
  File "/home/airflow/.local/lib/python3.12/site-packages/airflow/utils/session.py", line 97, in wrapper
    return func(*args, session=session, **kwargs)
           ^^^^^^^^^^^^^^^^^^^^^^^^^^^^^^^^^^^^^^
  File "/home/airflow/.local/lib/python3.12/site-packages/airflow/models/taskinstance.py", line 3004, in _run_raw_task
    return _run_raw_task(
           ^^^^^^^^^^^^^^
  File "/home/airflow/.local/lib/python3.12/site-packages/airflow/models/taskinstance.py", line 273, in _run_raw_task
    TaskInstance._execute_task_with_callbacks(
  File "/home/airflow/.local/lib/python3.12/site-packages/airflow/models/taskinstance.py", line 3158, in _execute_task_with_callbacks
    result = self._execute_task(context, task_orig)
             ^^^^^^^^^^^^^^^^^^^^^^^^^^^^^^^^^^^^^^
  File "/home/airflow/.local/lib/python3.12/site-packages/airflow/models/taskinstance.py", line 3182, in _execute_task
    return _execute_task(self, context, task_orig)
           ^^^^^^^^^^^^^^^^^^^^^^^^^^^^^^^^^^^^^^^
  File "/home/airflow/.local/lib/python3.12/site-packages/airflow/models/taskinstance.py", line 767, in _execute_task
    result = _execute_callable(context=context, **execute_callable_kwargs)
             ^^^^^^^^^^^^^^^^^^^^^^^^^^^^^^^^^^^^^^^^^^^^^^^^^^^^^^^^^^^^^
  File "/home/airflow/.local/lib/python3.12/site-packages/airflow/models/taskinstance.py", line 733, in _execute_callable
    return ExecutionCallableRunner(
           ^^^^^^^^^^^^^^^^^^^^^^^^
  File "/home/airflow/.local/lib/python3.12/site-packages/airflow/utils/operator_helpers.py", line 252, in run
    return self.func(*args, **kwargs)
           ^^^^^^^^^^^^^^^^^^^^^^^^^^
  File "/home/airflow/.local/lib/python3.12/site-packages/airflow/models/baseoperator.py", line 406, in wrapper
    return func(self, *args, **kwargs)
           ^^^^^^^^^^^^^^^^^^^^^^^^^^^
  File "/home/airflow/.local/lib/python3.12/site-packages/airflow/operators/bash.py", line 249, in execute
    raise AirflowException(
airflow.exceptions.AirflowException: Bash command failed. The command returned a non-zero exit code 1.
[2025-09-09T15:26:59.867+0000] {local_task_job_runner.py:266} INFO - Task exited with return code 1
[2025-09-09T15:26:59.986+0000] {taskinstance.py:3900} INFO - 0 downstream tasks scheduled from follow-on schedule check
[2025-09-09T15:27:00.010+0000] {local_task_job_runner.py:245} INFO - ::endgroup::
