[2025-09-14T08:47:06.373+0000] {local_task_job_runner.py:123} INFO - ::group::Pre task execution logs
[2025-09-14T08:47:06.470+0000] {taskinstance.py:2612} INFO - Dependencies all met for dep_context=non-requeueable deps ti=<TaskInstance: currency_etl.analyze scheduled__2025-09-12T16:00:00+00:00 [queued]>
[2025-09-14T08:47:06.500+0000] {taskinstance.py:2612} INFO - Dependencies all met for dep_context=requeueable deps ti=<TaskInstance: currency_etl.analyze scheduled__2025-09-12T16:00:00+00:00 [queued]>
[2025-09-14T08:47:06.502+0000] {taskinstance.py:2865} INFO - Starting attempt 3 of 4
[2025-09-14T08:47:06.548+0000] {taskinstance.py:2888} INFO - Executing <Task(BashOperator): analyze> on 2025-09-12 16:00:00+00:00
[2025-09-14T08:47:06.582+0000] {standard_task_runner.py:104} INFO - Running: ['***', 'tasks', 'run', 'currency_etl', 'analyze', 'scheduled__2025-09-12T16:00:00+00:00', '--job-id', '253', '--raw', '--subdir', 'DAGS_FOLDER/currency_etl.py', '--cfg-path', '/tmp/tmp2zpap1_5']
[2025-09-14T08:47:06.592+0000] {standard_task_runner.py:105} INFO - Job 253: Subtask analyze
[2025-09-14T08:47:06.595+0000] {logging_mixin.py:190} WARNING - /home/***/.local/lib/python3.12/site-packages/***/task/task_runner/standard_task_runner.py:70 DeprecationWarning: This process (pid=2217) is multi-threaded, use of fork() may lead to deadlocks in the child.
[2025-09-14T08:47:06.597+0000] {standard_task_runner.py:72} INFO - Started process 2218 to run task
[2025-09-14T08:47:07.446+0000] {task_command.py:467} INFO - Running <TaskInstance: currency_etl.analyze scheduled__2025-09-12T16:00:00+00:00 [running]> on host 6eb00eb09733
[2025-09-14T08:47:08.228+0000] {taskinstance.py:3131} INFO - Exporting env vars: AIRFLOW_CTX_DAG_OWNER='***' AIRFLOW_CTX_DAG_ID='currency_etl' AIRFLOW_CTX_TASK_ID='analyze' AIRFLOW_CTX_EXECUTION_DATE='2025-09-12T16:00:00+00:00' AIRFLOW_CTX_TRY_NUMBER='3' AIRFLOW_CTX_DAG_RUN_ID='scheduled__2025-09-12T16:00:00+00:00'
[2025-09-14T08:47:08.230+0000] {taskinstance.py:731} INFO - ::endgroup::
[2025-09-14T08:47:08.284+0000] {subprocess.py:63} INFO - Tmp dir root location: /tmp
[2025-09-14T08:47:08.288+0000] {subprocess.py:75} INFO - Running command: ['/usr/bin/bash', '-c', 'python /opt/***/src/analyze.py']
[2025-09-14T08:47:08.319+0000] {subprocess.py:86} INFO - Output:
[2025-09-14T08:47:08.510+0000] {subprocess.py:93} INFO - python: can't open file '/opt/***/src/analyze.py': [Errno 2] No such file or directory
[2025-09-14T08:47:08.519+0000] {subprocess.py:97} INFO - Command exited with return code 2
[2025-09-14T08:47:08.612+0000] {taskinstance.py:3310} ERROR - Task failed with exception
Traceback (most recent call last):
  File "/home/airflow/.local/lib/python3.12/site-packages/airflow/models/taskinstance.py", line 767, in _execute_task
    result = _execute_callable(context=context, **execute_callable_kwargs)
             ^^^^^^^^^^^^^^^^^^^^^^^^^^^^^^^^^^^^^^^^^^^^^^^^^^^^^^^^^^^^^
  File "/home/airflow/.local/lib/python3.12/site-packages/airflow/models/taskinstance.py", line 733, in _execute_callable
    return ExecutionCallableRunner(
           ^^^^^^^^^^^^^^^^^^^^^^^^
  File "/home/airflow/.local/lib/python3.12/site-packages/airflow/utils/operator_helpers.py", line 252, in run
    return self.func(*args, **kwargs)
           ^^^^^^^^^^^^^^^^^^^^^^^^^^
  File "/home/airflow/.local/lib/python3.12/site-packages/airflow/models/baseoperator.py", line 406, in wrapper
    return func(self, *args, **kwargs)
           ^^^^^^^^^^^^^^^^^^^^^^^^^^^
  File "/home/airflow/.local/lib/python3.12/site-packages/airflow/operators/bash.py", line 249, in execute
    raise AirflowException(
airflow.exceptions.AirflowException: Bash command failed. The command returned a non-zero exit code 2.
[2025-09-14T08:47:08.643+0000] {taskinstance.py:1225} INFO - Marking task as UP_FOR_RETRY. dag_id=currency_etl, task_id=analyze, run_id=scheduled__2025-09-12T16:00:00+00:00, execution_date=20250912T160000, start_date=20250914T084706, end_date=20250914T084708
[2025-09-14T08:47:08.702+0000] {taskinstance.py:340} INFO - ::group::Post task execution logs
[2025-09-14T08:47:08.704+0000] {standard_task_runner.py:124} ERROR - Failed to execute job 253 for task analyze (Bash command failed. The command returned a non-zero exit code 2.; 2218)
Traceback (most recent call last):
  File "/home/airflow/.local/lib/python3.12/site-packages/airflow/task/task_runner/standard_task_runner.py", line 117, in _start_by_fork
    ret = args.func(args, dag=self.dag)
          ^^^^^^^^^^^^^^^^^^^^^^^^^^^^^
  File "/home/airflow/.local/lib/python3.12/site-packages/airflow/cli/cli_config.py", line 49, in command
    return func(*args, **kwargs)
           ^^^^^^^^^^^^^^^^^^^^^
  File "/home/airflow/.local/lib/python3.12/site-packages/airflow/utils/cli.py", line 115, in wrapper
    return f(*args, **kwargs)
           ^^^^^^^^^^^^^^^^^^
  File "/home/airflow/.local/lib/python3.12/site-packages/airflow/cli/commands/task_command.py", line 483, in task_run
    task_return_code = _run_task_by_selected_method(args, _dag, ti)
                       ^^^^^^^^^^^^^^^^^^^^^^^^^^^^^^^^^^^^^^^^^^^^
  File "/home/airflow/.local/lib/python3.12/site-packages/airflow/cli/commands/task_command.py", line 256, in _run_task_by_selected_method
    return _run_raw_task(args, ti)
           ^^^^^^^^^^^^^^^^^^^^^^^
  File "/home/airflow/.local/lib/python3.12/site-packages/airflow/cli/commands/task_command.py", line 341, in _run_raw_task
    return ti._run_raw_task(
           ^^^^^^^^^^^^^^^^^
  File "/home/airflow/.local/lib/python3.12/site-packages/airflow/utils/session.py", line 97, in wrapper
    return func(*args, session=session, **kwargs)
           ^^^^^^^^^^^^^^^^^^^^^^^^^^^^^^^^^^^^^^
  File "/home/airflow/.local/lib/python3.12/site-packages/airflow/models/taskinstance.py", line 3004, in _run_raw_task
    return _run_raw_task(
           ^^^^^^^^^^^^^^
  File "/home/airflow/.local/lib/python3.12/site-packages/airflow/models/taskinstance.py", line 273, in _run_raw_task
    TaskInstance._execute_task_with_callbacks(
  File "/home/airflow/.local/lib/python3.12/site-packages/airflow/models/taskinstance.py", line 3158, in _execute_task_with_callbacks
    result = self._execute_task(context, task_orig)
             ^^^^^^^^^^^^^^^^^^^^^^^^^^^^^^^^^^^^^^
  File "/home/airflow/.local/lib/python3.12/site-packages/airflow/models/taskinstance.py", line 3182, in _execute_task
    return _execute_task(self, context, task_orig)
           ^^^^^^^^^^^^^^^^^^^^^^^^^^^^^^^^^^^^^^^
  File "/home/airflow/.local/lib/python3.12/site-packages/airflow/models/taskinstance.py", line 767, in _execute_task
    result = _execute_callable(context=context, **execute_callable_kwargs)
             ^^^^^^^^^^^^^^^^^^^^^^^^^^^^^^^^^^^^^^^^^^^^^^^^^^^^^^^^^^^^^
  File "/home/airflow/.local/lib/python3.12/site-packages/airflow/models/taskinstance.py", line 733, in _execute_callable
    return ExecutionCallableRunner(
           ^^^^^^^^^^^^^^^^^^^^^^^^
  File "/home/airflow/.local/lib/python3.12/site-packages/airflow/utils/operator_helpers.py", line 252, in run
    return self.func(*args, **kwargs)
           ^^^^^^^^^^^^^^^^^^^^^^^^^^
  File "/home/airflow/.local/lib/python3.12/site-packages/airflow/models/baseoperator.py", line 406, in wrapper
    return func(self, *args, **kwargs)
           ^^^^^^^^^^^^^^^^^^^^^^^^^^^
  File "/home/airflow/.local/lib/python3.12/site-packages/airflow/operators/bash.py", line 249, in execute
    raise AirflowException(
airflow.exceptions.AirflowException: Bash command failed. The command returned a non-zero exit code 2.
[2025-09-14T08:47:08.739+0000] {local_task_job_runner.py:266} INFO - Task exited with return code 1
[2025-09-14T08:47:08.867+0000] {taskinstance.py:3900} INFO - 0 downstream tasks scheduled from follow-on schedule check
[2025-09-14T08:47:08.873+0000] {local_task_job_runner.py:245} INFO - ::endgroup::
