[2025-09-13T16:28:50.408+0000] {local_task_job_runner.py:123} INFO - ::group::Pre task execution logs
[2025-09-13T16:28:50.766+0000] {taskinstance.py:2612} INFO - Dependencies all met for dep_context=non-requeueable deps ti=<TaskInstance: currency_etl.analyze manual__2025-09-13T10:27:29.902252+00:00 [queued]>
[2025-09-13T16:28:50.912+0000] {taskinstance.py:2612} INFO - Dependencies all met for dep_context=requeueable deps ti=<TaskInstance: currency_etl.analyze manual__2025-09-13T10:27:29.902252+00:00 [queued]>
[2025-09-13T16:28:50.962+0000] {taskinstance.py:2865} INFO - Starting attempt 2 of 2
[2025-09-13T16:28:51.222+0000] {taskinstance.py:2888} INFO - Executing <Task(BashOperator): analyze> on 2025-09-13 10:27:29.902252+00:00
[2025-09-13T16:28:51.253+0000] {standard_task_runner.py:104} INFO - Running: ['***', 'tasks', 'run', 'currency_etl', 'analyze', 'manual__2025-09-13T10:27:29.902252+00:00', '--job-id', '241', '--raw', '--subdir', 'DAGS_FOLDER/currency_etl.py', '--cfg-path', '/tmp/tmpwhsrrb3_']
[2025-09-13T16:28:51.268+0000] {standard_task_runner.py:105} INFO - Job 241: Subtask analyze
[2025-09-13T16:28:51.279+0000] {logging_mixin.py:190} WARNING - /home/***/.local/lib/python3.12/site-packages/***/task/task_runner/standard_task_runner.py:70 DeprecationWarning: This process (pid=1073) is multi-threaded, use of fork() may lead to deadlocks in the child.
[2025-09-13T16:28:51.285+0000] {standard_task_runner.py:72} INFO - Started process 1076 to run task
[2025-09-13T16:28:52.436+0000] {task_command.py:467} INFO - Running <TaskInstance: currency_etl.analyze manual__2025-09-13T10:27:29.902252+00:00 [running]> on host 6eb00eb09733
[2025-09-13T16:28:53.130+0000] {taskinstance.py:3131} INFO - Exporting env vars: AIRFLOW_CTX_DAG_OWNER='***' AIRFLOW_CTX_DAG_ID='currency_etl' AIRFLOW_CTX_TASK_ID='analyze' AIRFLOW_CTX_EXECUTION_DATE='2025-09-13T10:27:29.902252+00:00' AIRFLOW_CTX_TRY_NUMBER='2' AIRFLOW_CTX_DAG_RUN_ID='manual__2025-09-13T10:27:29.902252+00:00'
[2025-09-13T16:28:53.133+0000] {taskinstance.py:731} INFO - ::endgroup::
[2025-09-13T16:28:53.224+0000] {subprocess.py:63} INFO - Tmp dir root location: /tmp
[2025-09-13T16:28:53.230+0000] {subprocess.py:75} INFO - Running command: ['/usr/bin/bash', '-c', 'python /opt/***/scripts/analyze.py']
[2025-09-13T16:28:53.308+0000] {subprocess.py:86} INFO - Output:
[2025-09-13T17:50:29.247+0000] {job.py:229} INFO - Heartbeat recovered after 4899.99 seconds
[2025-09-13T17:50:31.040+0000] {subprocess.py:93} INFO - Traceback (most recent call last):
[2025-09-13T17:50:31.042+0000] {subprocess.py:93} INFO -   File "/home/***/.local/lib/python3.12/site-packages/sqlalchemy/engine/base.py", line 1910, in _execute_context
[2025-09-13T17:50:31.043+0000] {subprocess.py:93} INFO -     self.dialect.do_execute(
[2025-09-13T17:50:31.044+0000] {subprocess.py:93} INFO -   File "/home/***/.local/lib/python3.12/site-packages/sqlalchemy/engine/default.py", line 736, in do_execute
[2025-09-13T17:50:31.045+0000] {subprocess.py:93} INFO -     cursor.execute(statement, parameters)
[2025-09-13T17:50:31.046+0000] {subprocess.py:93} INFO - psycopg2.errors.InvalidColumnReference: argument of OFFSET must not contain variables
[2025-09-13T17:50:31.046+0000] {subprocess.py:93} INFO - LINE 17:             OFFSET GREATEST(LEAST(days_info.cnt - 1, 30), 0)...
[2025-09-13T17:50:31.050+0000] {subprocess.py:93} INFO -                                            ^
[2025-09-13T17:50:31.051+0000] {subprocess.py:93} INFO - 
[2025-09-13T17:50:31.052+0000] {subprocess.py:93} INFO - 
[2025-09-13T17:50:31.053+0000] {subprocess.py:93} INFO - The above exception was the direct cause of the following exception:
[2025-09-13T17:50:31.054+0000] {subprocess.py:93} INFO - 
[2025-09-13T17:50:31.054+0000] {subprocess.py:93} INFO - Traceback (most recent call last):
[2025-09-13T17:50:31.055+0000] {subprocess.py:93} INFO -   File "/opt/***/scripts/analyze.py", line 123, in <module>
[2025-09-13T17:50:31.056+0000] {subprocess.py:93} INFO -     res = conn.execute(text(q)).fetchall()
[2025-09-13T17:50:31.056+0000] {subprocess.py:93} INFO -           ^^^^^^^^^^^^^^^^^^^^^
[2025-09-13T17:50:31.057+0000] {subprocess.py:93} INFO -   File "/home/***/.local/lib/python3.12/site-packages/sqlalchemy/engine/base.py", line 1385, in execute
[2025-09-13T17:50:31.058+0000] {subprocess.py:93} INFO -     return meth(self, multiparams, params, _EMPTY_EXECUTION_OPTS)
[2025-09-13T17:50:31.059+0000] {subprocess.py:93} INFO -            ^^^^^^^^^^^^^^^^^^^^^^^^^^^^^^^^^^^^^^^^^^^^^^^^^^^^^^
[2025-09-13T17:50:31.059+0000] {subprocess.py:93} INFO -   File "/home/***/.local/lib/python3.12/site-packages/sqlalchemy/sql/elements.py", line 334, in _execute_on_connection
[2025-09-13T17:50:31.066+0000] {subprocess.py:93} INFO -     return connection._execute_clauseelement(
[2025-09-13T17:50:31.067+0000] {subprocess.py:93} INFO -            ^^^^^^^^^^^^^^^^^^^^^^^^^^^^^^^^^^
[2025-09-13T17:50:31.068+0000] {subprocess.py:93} INFO -   File "/home/***/.local/lib/python3.12/site-packages/sqlalchemy/engine/base.py", line 1577, in _execute_clauseelement
[2025-09-13T17:50:31.068+0000] {subprocess.py:93} INFO -     ret = self._execute_context(
[2025-09-13T17:50:31.069+0000] {subprocess.py:93} INFO -           ^^^^^^^^^^^^^^^^^^^^^^
[2025-09-13T17:50:31.078+0000] {subprocess.py:93} INFO -   File "/home/***/.local/lib/python3.12/site-packages/sqlalchemy/engine/base.py", line 1953, in _execute_context
[2025-09-13T17:50:31.079+0000] {subprocess.py:93} INFO -     self._handle_dbapi_exception(
[2025-09-13T17:50:31.079+0000] {subprocess.py:93} INFO -   File "/home/***/.local/lib/python3.12/site-packages/sqlalchemy/engine/base.py", line 2134, in _handle_dbapi_exception
[2025-09-13T17:50:31.080+0000] {subprocess.py:93} INFO -     util.raise_(
[2025-09-13T17:50:31.082+0000] {subprocess.py:93} INFO -   File "/home/***/.local/lib/python3.12/site-packages/sqlalchemy/util/compat.py", line 211, in raise_
[2025-09-13T17:50:31.084+0000] {subprocess.py:93} INFO -     raise exception
[2025-09-13T17:50:31.085+0000] {subprocess.py:93} INFO -   File "/home/***/.local/lib/python3.12/site-packages/sqlalchemy/engine/base.py", line 1910, in _execute_context
[2025-09-13T17:50:31.086+0000] {subprocess.py:93} INFO -     self.dialect.do_execute(
[2025-09-13T17:50:31.086+0000] {subprocess.py:93} INFO -   File "/home/***/.local/lib/python3.12/site-packages/sqlalchemy/engine/default.py", line 736, in do_execute
[2025-09-13T17:50:31.087+0000] {subprocess.py:93} INFO -     cursor.execute(statement, parameters)
[2025-09-13T17:50:31.088+0000] {subprocess.py:93} INFO - sqlalchemy.exc.ProgrammingError: (psycopg2.errors.InvalidColumnReference) argument of OFFSET must not contain variables
[2025-09-13T17:50:31.088+0000] {subprocess.py:93} INFO - LINE 17:             OFFSET GREATEST(LEAST(days_info.cnt - 1, 30), 0)...
[2025-09-13T17:50:31.089+0000] {subprocess.py:93} INFO -                                            ^
[2025-09-13T17:50:31.090+0000] {subprocess.py:93} INFO - 
[2025-09-13T17:50:31.091+0000] {subprocess.py:93} INFO - [SQL:
[2025-09-13T17:50:31.091+0000] {subprocess.py:93} INFO -         WITH last AS (
[2025-09-13T17:50:31.092+0000] {subprocess.py:93} INFO -             SELECT rate
[2025-09-13T17:50:31.093+0000] {subprocess.py:93} INFO -             FROM exchange_rates
[2025-09-13T17:50:31.093+0000] {subprocess.py:93} INFO -             WHERE cc='USD'
[2025-09-13T17:50:31.094+0000] {subprocess.py:93} INFO -             ORDER BY exchangedate DESC
[2025-09-13T17:50:31.094+0000] {subprocess.py:93} INFO -             LIMIT 1
[2025-09-13T17:50:31.095+0000] {subprocess.py:93} INFO -         ),
[2025-09-13T17:50:31.095+0000] {subprocess.py:93} INFO -         days_info AS (
[2025-09-13T17:50:31.096+0000] {subprocess.py:93} INFO -             SELECT COUNT(*) AS cnt FROM exchange_rates WHERE cc='USD'
[2025-09-13T17:50:31.096+0000] {subprocess.py:93} INFO -         ),
[2025-09-13T17:50:31.096+0000] {subprocess.py:93} INFO -         ago AS (
[2025-09-13T17:50:31.097+0000] {subprocess.py:93} INFO -             SELECT rate
[2025-09-13T17:50:31.097+0000] {subprocess.py:93} INFO -             FROM exchange_rates, days_info
[2025-09-13T17:50:31.098+0000] {subprocess.py:93} INFO -             WHERE cc='USD'
[2025-09-13T17:50:31.098+0000] {subprocess.py:93} INFO -             ORDER BY exchangedate DESC
[2025-09-13T17:50:31.099+0000] {subprocess.py:93} INFO -             OFFSET GREATEST(LEAST(days_info.cnt - 1, 30), 0) LIMIT 1
[2025-09-13T17:50:31.099+0000] {subprocess.py:93} INFO -         )
[2025-09-13T17:50:31.100+0000] {subprocess.py:93} INFO -         SELECT last.rate - ago.rate AS diff_usd
[2025-09-13T17:50:31.100+0000] {subprocess.py:93} INFO -         FROM last, ago;
[2025-09-13T17:50:31.107+0000] {subprocess.py:93} INFO -     ]
[2025-09-13T17:50:31.108+0000] {subprocess.py:93} INFO - (Background on this error at: https://sqlalche.me/e/14/f405)
[2025-09-13T17:50:31.569+0000] {subprocess.py:97} INFO - Command exited with return code 1
[2025-09-13T17:50:31.623+0000] {taskinstance.py:3310} ERROR - Task failed with exception
Traceback (most recent call last):
  File "/home/airflow/.local/lib/python3.12/site-packages/airflow/models/taskinstance.py", line 767, in _execute_task
    result = _execute_callable(context=context, **execute_callable_kwargs)
             ^^^^^^^^^^^^^^^^^^^^^^^^^^^^^^^^^^^^^^^^^^^^^^^^^^^^^^^^^^^^^
  File "/home/airflow/.local/lib/python3.12/site-packages/airflow/models/taskinstance.py", line 733, in _execute_callable
    return ExecutionCallableRunner(
           ^^^^^^^^^^^^^^^^^^^^^^^^
  File "/home/airflow/.local/lib/python3.12/site-packages/airflow/utils/operator_helpers.py", line 252, in run
    return self.func(*args, **kwargs)
           ^^^^^^^^^^^^^^^^^^^^^^^^^^
  File "/home/airflow/.local/lib/python3.12/site-packages/airflow/models/baseoperator.py", line 406, in wrapper
    return func(self, *args, **kwargs)
           ^^^^^^^^^^^^^^^^^^^^^^^^^^^
  File "/home/airflow/.local/lib/python3.12/site-packages/airflow/operators/bash.py", line 249, in execute
    raise AirflowException(
airflow.exceptions.AirflowException: Bash command failed. The command returned a non-zero exit code 1.
[2025-09-13T17:50:31.640+0000] {taskinstance.py:1225} INFO - Marking task as FAILED. dag_id=currency_etl, task_id=analyze, run_id=manual__2025-09-13T10:27:29.902252+00:00, execution_date=20250913T102729, start_date=20250913T162850, end_date=20250913T175031
[2025-09-13T17:50:31.699+0000] {taskinstance.py:340} INFO - ::group::Post task execution logs
[2025-09-13T17:50:31.703+0000] {standard_task_runner.py:124} ERROR - Failed to execute job 241 for task analyze (Bash command failed. The command returned a non-zero exit code 1.; 1076)
Traceback (most recent call last):
  File "/home/airflow/.local/lib/python3.12/site-packages/airflow/task/task_runner/standard_task_runner.py", line 117, in _start_by_fork
    ret = args.func(args, dag=self.dag)
          ^^^^^^^^^^^^^^^^^^^^^^^^^^^^^
  File "/home/airflow/.local/lib/python3.12/site-packages/airflow/cli/cli_config.py", line 49, in command
    return func(*args, **kwargs)
           ^^^^^^^^^^^^^^^^^^^^^
  File "/home/airflow/.local/lib/python3.12/site-packages/airflow/utils/cli.py", line 115, in wrapper
    return f(*args, **kwargs)
           ^^^^^^^^^^^^^^^^^^
  File "/home/airflow/.local/lib/python3.12/site-packages/airflow/cli/commands/task_command.py", line 483, in task_run
    task_return_code = _run_task_by_selected_method(args, _dag, ti)
                       ^^^^^^^^^^^^^^^^^^^^^^^^^^^^^^^^^^^^^^^^^^^^
  File "/home/airflow/.local/lib/python3.12/site-packages/airflow/cli/commands/task_command.py", line 256, in _run_task_by_selected_method
    return _run_raw_task(args, ti)
           ^^^^^^^^^^^^^^^^^^^^^^^
  File "/home/airflow/.local/lib/python3.12/site-packages/airflow/cli/commands/task_command.py", line 341, in _run_raw_task
    return ti._run_raw_task(
           ^^^^^^^^^^^^^^^^^
  File "/home/airflow/.local/lib/python3.12/site-packages/airflow/utils/session.py", line 97, in wrapper
    return func(*args, session=session, **kwargs)
           ^^^^^^^^^^^^^^^^^^^^^^^^^^^^^^^^^^^^^^
  File "/home/airflow/.local/lib/python3.12/site-packages/airflow/models/taskinstance.py", line 3004, in _run_raw_task
    return _run_raw_task(
           ^^^^^^^^^^^^^^
  File "/home/airflow/.local/lib/python3.12/site-packages/airflow/models/taskinstance.py", line 273, in _run_raw_task
    TaskInstance._execute_task_with_callbacks(
  File "/home/airflow/.local/lib/python3.12/site-packages/airflow/models/taskinstance.py", line 3158, in _execute_task_with_callbacks
    result = self._execute_task(context, task_orig)
             ^^^^^^^^^^^^^^^^^^^^^^^^^^^^^^^^^^^^^^
  File "/home/airflow/.local/lib/python3.12/site-packages/airflow/models/taskinstance.py", line 3182, in _execute_task
    return _execute_task(self, context, task_orig)
           ^^^^^^^^^^^^^^^^^^^^^^^^^^^^^^^^^^^^^^^
  File "/home/airflow/.local/lib/python3.12/site-packages/airflow/models/taskinstance.py", line 767, in _execute_task
    result = _execute_callable(context=context, **execute_callable_kwargs)
             ^^^^^^^^^^^^^^^^^^^^^^^^^^^^^^^^^^^^^^^^^^^^^^^^^^^^^^^^^^^^^
  File "/home/airflow/.local/lib/python3.12/site-packages/airflow/models/taskinstance.py", line 733, in _execute_callable
    return ExecutionCallableRunner(
           ^^^^^^^^^^^^^^^^^^^^^^^^
  File "/home/airflow/.local/lib/python3.12/site-packages/airflow/utils/operator_helpers.py", line 252, in run
    return self.func(*args, **kwargs)
           ^^^^^^^^^^^^^^^^^^^^^^^^^^
  File "/home/airflow/.local/lib/python3.12/site-packages/airflow/models/baseoperator.py", line 406, in wrapper
    return func(self, *args, **kwargs)
           ^^^^^^^^^^^^^^^^^^^^^^^^^^^
  File "/home/airflow/.local/lib/python3.12/site-packages/airflow/operators/bash.py", line 249, in execute
    raise AirflowException(
airflow.exceptions.AirflowException: Bash command failed. The command returned a non-zero exit code 1.
[2025-09-13T17:50:31.770+0000] {local_task_job_runner.py:266} INFO - Task exited with return code 1
[2025-09-13T17:50:31.937+0000] {taskinstance.py:3900} INFO - 0 downstream tasks scheduled from follow-on schedule check
[2025-09-13T17:50:31.967+0000] {local_task_job_runner.py:245} INFO - ::endgroup::
