[2025-09-13T10:08:38.730+0000] {local_task_job_runner.py:123} INFO - ::group::Pre task execution logs
[2025-09-13T10:08:38.801+0000] {taskinstance.py:2612} INFO - Dependencies all met for dep_context=non-requeueable deps ti=<TaskInstance: currency_etl.analyze manual__2025-09-13T10:06:02.725509+00:00 [queued]>
[2025-09-13T10:08:38.818+0000] {taskinstance.py:2612} INFO - Dependencies all met for dep_context=requeueable deps ti=<TaskInstance: currency_etl.analyze manual__2025-09-13T10:06:02.725509+00:00 [queued]>
[2025-09-13T10:08:38.819+0000] {taskinstance.py:2865} INFO - Starting attempt 2 of 3
[2025-09-13T10:08:38.848+0000] {taskinstance.py:2888} INFO - Executing <Task(BashOperator): analyze> on 2025-09-13 10:06:02.725509+00:00
[2025-09-13T10:08:38.867+0000] {standard_task_runner.py:104} INFO - Running: ['***', 'tasks', 'run', 'currency_etl', 'analyze', 'manual__2025-09-13T10:06:02.725509+00:00', '--job-id', '227', '--raw', '--subdir', 'DAGS_FOLDER/currency_etl.py', '--cfg-path', '/tmp/tmp1ed9vech']
[2025-09-13T10:08:38.873+0000] {standard_task_runner.py:105} INFO - Job 227: Subtask analyze
[2025-09-13T10:08:38.872+0000] {logging_mixin.py:190} WARNING - /home/***/.local/lib/python3.12/site-packages/***/task/task_runner/standard_task_runner.py:70 DeprecationWarning: This process (pid=683) is multi-threaded, use of fork() may lead to deadlocks in the child.
[2025-09-13T10:08:38.875+0000] {standard_task_runner.py:72} INFO - Started process 684 to run task
[2025-09-13T10:08:39.098+0000] {task_command.py:467} INFO - Running <TaskInstance: currency_etl.analyze manual__2025-09-13T10:06:02.725509+00:00 [running]> on host 6eb00eb09733
[2025-09-13T10:08:39.411+0000] {taskinstance.py:3131} INFO - Exporting env vars: AIRFLOW_CTX_DAG_OWNER='***' AIRFLOW_CTX_DAG_ID='currency_etl' AIRFLOW_CTX_TASK_ID='analyze' AIRFLOW_CTX_EXECUTION_DATE='2025-09-13T10:06:02.725509+00:00' AIRFLOW_CTX_TRY_NUMBER='2' AIRFLOW_CTX_DAG_RUN_ID='manual__2025-09-13T10:06:02.725509+00:00'
[2025-09-13T10:08:39.413+0000] {taskinstance.py:731} INFO - ::endgroup::
[2025-09-13T10:08:39.436+0000] {subprocess.py:63} INFO - Tmp dir root location: /tmp
[2025-09-13T10:08:39.439+0000] {subprocess.py:75} INFO - Running command: ['/usr/bin/bash', '-c', 'python /opt/***/scripts/analyze.py']
[2025-09-13T10:08:39.462+0000] {subprocess.py:86} INFO - Output:
[2025-09-13T10:08:41.467+0000] {subprocess.py:93} INFO - /opt/***/scripts/analyze.py:141: DeprecationWarning: datetime.datetime.utcnow() is deprecated and scheduled for removal in a future version. Use timezone-aware objects to represent datetimes in UTC: datetime.datetime.now(datetime.UTC).
[2025-09-13T10:08:41.468+0000] {subprocess.py:93} INFO -   today = datetime.utcnow().strftime("%Y-%m-%d")
[2025-09-13T10:08:41.494+0000] {subprocess.py:93} INFO - Traceback (most recent call last):
[2025-09-13T10:08:41.495+0000] {subprocess.py:93} INFO -   File "/opt/***/scripts/analyze.py", line 157, in <module>
[2025-09-13T10:08:41.498+0000] {subprocess.py:93} INFO -     f"üíµ –ü–æ—Ç–æ—á–Ω–∏–π –∫—É—Ä—Å USD: {usd['last']['last_usd']:.2f} –≥—Ä–Ω",
[2025-09-13T10:08:41.499+0000] {subprocess.py:93} INFO -                              ~~~~~~~~~~~^^^^^^^^^^^^
[2025-09-13T10:08:41.499+0000] {subprocess.py:93} INFO - TypeError: 'float' object is not subscriptable
[2025-09-13T10:08:41.646+0000] {subprocess.py:97} INFO - Command exited with return code 1
[2025-09-13T10:08:41.700+0000] {taskinstance.py:3310} ERROR - Task failed with exception
Traceback (most recent call last):
  File "/home/airflow/.local/lib/python3.12/site-packages/airflow/models/taskinstance.py", line 767, in _execute_task
    result = _execute_callable(context=context, **execute_callable_kwargs)
             ^^^^^^^^^^^^^^^^^^^^^^^^^^^^^^^^^^^^^^^^^^^^^^^^^^^^^^^^^^^^^
  File "/home/airflow/.local/lib/python3.12/site-packages/airflow/models/taskinstance.py", line 733, in _execute_callable
    return ExecutionCallableRunner(
           ^^^^^^^^^^^^^^^^^^^^^^^^
  File "/home/airflow/.local/lib/python3.12/site-packages/airflow/utils/operator_helpers.py", line 252, in run
    return self.func(*args, **kwargs)
           ^^^^^^^^^^^^^^^^^^^^^^^^^^
  File "/home/airflow/.local/lib/python3.12/site-packages/airflow/models/baseoperator.py", line 406, in wrapper
    return func(self, *args, **kwargs)
           ^^^^^^^^^^^^^^^^^^^^^^^^^^^
  File "/home/airflow/.local/lib/python3.12/site-packages/airflow/operators/bash.py", line 249, in execute
    raise AirflowException(
airflow.exceptions.AirflowException: Bash command failed. The command returned a non-zero exit code 1.
[2025-09-13T10:08:41.715+0000] {taskinstance.py:1225} INFO - Marking task as UP_FOR_RETRY. dag_id=currency_etl, task_id=analyze, run_id=manual__2025-09-13T10:06:02.725509+00:00, execution_date=20250913T100602, start_date=20250913T100838, end_date=20250913T100841
[2025-09-13T10:08:41.768+0000] {taskinstance.py:340} INFO - ::group::Post task execution logs
[2025-09-13T10:08:41.769+0000] {standard_task_runner.py:124} ERROR - Failed to execute job 227 for task analyze (Bash command failed. The command returned a non-zero exit code 1.; 684)
Traceback (most recent call last):
  File "/home/airflow/.local/lib/python3.12/site-packages/airflow/task/task_runner/standard_task_runner.py", line 117, in _start_by_fork
    ret = args.func(args, dag=self.dag)
          ^^^^^^^^^^^^^^^^^^^^^^^^^^^^^
  File "/home/airflow/.local/lib/python3.12/site-packages/airflow/cli/cli_config.py", line 49, in command
    return func(*args, **kwargs)
           ^^^^^^^^^^^^^^^^^^^^^
  File "/home/airflow/.local/lib/python3.12/site-packages/airflow/utils/cli.py", line 115, in wrapper
    return f(*args, **kwargs)
           ^^^^^^^^^^^^^^^^^^
  File "/home/airflow/.local/lib/python3.12/site-packages/airflow/cli/commands/task_command.py", line 483, in task_run
    task_return_code = _run_task_by_selected_method(args, _dag, ti)
                       ^^^^^^^^^^^^^^^^^^^^^^^^^^^^^^^^^^^^^^^^^^^^
  File "/home/airflow/.local/lib/python3.12/site-packages/airflow/cli/commands/task_command.py", line 256, in _run_task_by_selected_method
    return _run_raw_task(args, ti)
           ^^^^^^^^^^^^^^^^^^^^^^^
  File "/home/airflow/.local/lib/python3.12/site-packages/airflow/cli/commands/task_command.py", line 341, in _run_raw_task
    return ti._run_raw_task(
           ^^^^^^^^^^^^^^^^^
  File "/home/airflow/.local/lib/python3.12/site-packages/airflow/utils/session.py", line 97, in wrapper
    return func(*args, session=session, **kwargs)
           ^^^^^^^^^^^^^^^^^^^^^^^^^^^^^^^^^^^^^^
  File "/home/airflow/.local/lib/python3.12/site-packages/airflow/models/taskinstance.py", line 3004, in _run_raw_task
    return _run_raw_task(
           ^^^^^^^^^^^^^^
  File "/home/airflow/.local/lib/python3.12/site-packages/airflow/models/taskinstance.py", line 273, in _run_raw_task
    TaskInstance._execute_task_with_callbacks(
  File "/home/airflow/.local/lib/python3.12/site-packages/airflow/models/taskinstance.py", line 3158, in _execute_task_with_callbacks
    result = self._execute_task(context, task_orig)
             ^^^^^^^^^^^^^^^^^^^^^^^^^^^^^^^^^^^^^^
  File "/home/airflow/.local/lib/python3.12/site-packages/airflow/models/taskinstance.py", line 3182, in _execute_task
    return _execute_task(self, context, task_orig)
           ^^^^^^^^^^^^^^^^^^^^^^^^^^^^^^^^^^^^^^^
  File "/home/airflow/.local/lib/python3.12/site-packages/airflow/models/taskinstance.py", line 767, in _execute_task
    result = _execute_callable(context=context, **execute_callable_kwargs)
             ^^^^^^^^^^^^^^^^^^^^^^^^^^^^^^^^^^^^^^^^^^^^^^^^^^^^^^^^^^^^^
  File "/home/airflow/.local/lib/python3.12/site-packages/airflow/models/taskinstance.py", line 733, in _execute_callable
    return ExecutionCallableRunner(
           ^^^^^^^^^^^^^^^^^^^^^^^^
  File "/home/airflow/.local/lib/python3.12/site-packages/airflow/utils/operator_helpers.py", line 252, in run
    return self.func(*args, **kwargs)
           ^^^^^^^^^^^^^^^^^^^^^^^^^^
  File "/home/airflow/.local/lib/python3.12/site-packages/airflow/models/baseoperator.py", line 406, in wrapper
    return func(self, *args, **kwargs)
           ^^^^^^^^^^^^^^^^^^^^^^^^^^^
  File "/home/airflow/.local/lib/python3.12/site-packages/airflow/operators/bash.py", line 249, in execute
    raise AirflowException(
airflow.exceptions.AirflowException: Bash command failed. The command returned a non-zero exit code 1.
[2025-09-13T10:08:41.825+0000] {local_task_job_runner.py:266} INFO - Task exited with return code 1
[2025-09-13T10:08:41.898+0000] {taskinstance.py:3900} INFO - 0 downstream tasks scheduled from follow-on schedule check
[2025-09-13T10:08:41.903+0000] {local_task_job_runner.py:245} INFO - ::endgroup::
